Workbook
Name MATRIZ1: #REF!
Name MATRIZ1: #REF!
Name MATRIZ1: #REF!
Name MATRIZ2: #REF!
Name MATRIZ2: #REF!
Name MATRIZ2: #REF!
Name MATRIZ3: #REF!
Name MATRIZ3: #REF!
Name MATRIZ3: #REF!
Name MATRIZ4: #REF!
Name MATRIZ4: #REF!
Name MATRIZ4: #REF!
Name Q: #REF!
Name Q: #REF!
Name Q: #REF!
Name S: #REF!
Name S: #REF!
Name S: #REF!

Sheet COT. BSII, CF. 300, CF. 400
B1: {=+CELL("nombrearchivo")} -> C:\Users\fcola\Desktop\APPACCURATEK\[excel de prueba.xlsx]CUBICACION
B2: PRESUPUESTO:
B3: OBRA: | C3: TORRE KENEDY
B4: PRODUCTO: | C4: CAFCO 400
B5: ING. A CARGO: | O5: m²/bolsa
N6: Cafco 300 | O6: =+CUBICACION!Q4/E25 -> #DIV/0!
B7: RESUMEN | F7: RESUMEN | N7: Cafco 400 | O7: =+CUBICACION!Q3/E26 -> #DIV/0!
I8: =+I19/C9 -> 0.84988234 | J8: uf/m2 | N8: Blaze Shield II | O8: =+CUBICACION!Q2/E27 -> 2.0607611
B9: SUPERFICIE 1 | C9: =+SUM(CUBICACION!Q2:Q4) -> 1696.0064 | D9: m2 | F9: VALOR UF | G9: 40830 | H9: $ | I9: =+G19/C9 -> 34700.696 | J9: $/m2
B11: SUPERFICIE CAFCO 400 | C11: =+CUBICACION!Q3 -> 0 | D11: m2 | F11: VALOR DOLLAR | G11: 980 | H11: $ | K11: 0.35 | L11: Margen mat
B13: Rendimiento BSII/DIA | C13: 45 | D13: Bl/dia | F13: COSTO | G13: =+I111 -> 38254192 | H13: $ | I13: =+G13/G9 -> 936.91383 | J13: UF | K13: 0.35 | L13: Margen MOI | N13: 346.6 | O13: 0.328 | P13: =O13*N13 -> 113.6848
B15: Rendimiento CAFCO/DIA | C15: 35 | D15: Bl/dia | F15: MARGEN DE VENTA | G15: =+K112 -> 0.35 | H15: % | I15: =+G15 -> 0.35 | J15: % | K15: 0.35 | L15: Margen MOD | O15: 0.118 | P15: =O15*N13 -> 40.8988
B17: Rendimiento M2/BL | D17: m2/bl | F17: MARGEN DE VENTA | G17: =+G19-G13 -> 20598411 | H17: $ | I17: =+G17/G9 -> 504.49206 | J17: UF | K17: 0.35 | L17: Margen Equipos | O17: 0.087 | P17: =O17*N13 -> 30.1542
F19: PRECIO DE VENTA | G19: =+K111 -> 58852602 | H19: $ | I19: =+G19/G9 -> 1441.4059 | J19: UF | K19: 0.35 | L19: Margen GG | O19: =O13+O15+O17 -> 0.533 | P19: =P13+P15+P17 -> 184.7378
P21: =N13*O19 -> 184.7378
B22: ÍTEM Nº | C22: Descripcion | D22: Unidad | E22: Cantidad | F22: Costo Unitario | G22: Costo Total | H22: PERDIDA (%) | I22: Costo Total C/Perdida | J22: INCIDENCIA (%) | K22: Precio de Venta | M22: CUADRO DE OFERTA PARA CARTA
M23: Descripción | N23: Superficie m2 | O23: UF/m2 | P23: Total P.U. (UF) | Q23: %
B24: 1 | C24: MATERIALES | D24: =SUM(J25:J31) -> 0.57511998 | M24: Materiales Directos | N24: =+C9 -> 1696.0064 | O24: =+P24/N24 -> 0.48878432 | P24: =+Q24*P27 -> 828.98133 | Q24: =+D24 -> 0.57511998
B25: 1.1 | C25: Cafco 300 | D25: Bolsas | E25: =+CUBICACION!R4 -> 0 | F25: =16.75*G11*1.5 -> 24622.5 | G25: =+F25*E25 -> 0 | H25: 0.05 | I25: =+(G25*H25)+G25 -> 0 | J25: =I25/$I$111 -> 0 | K25: =+I25/(1-$K$11) -> 0 | M25: Mano de obra Directa e Indirecta | N25: =+N24 -> 1696.0064 | O25: =+P25/N25 -> 0.10262454 | P25: =+Q25*P27 -> 174.05188 | Q25: =+D33+D41 -> 0.12075147
B26: 1.2 | C26: Cafco 400 | D26: Bolsas | E26: =+CUBICACION!R3 -> 0 | F26: 26000 | G26: =+F26*E26 -> 0 | H26: 0.05 | I26: =+(G26*H26)+G26 -> 0 | J26: =I26/$I$111 -> 0 | K26: =+I26/(1-$K$11) -> 0 | M26: Gastos Generales | N26: =+N25 -> 1696.0064 | O26: =+P26/N26 -> 0.25847348 | P26: =+Q26*P27 -> 438.37267 | Q26: =+D48+D57+D66+D74+D81+D89+D96+D108 -> 0.30412854
B27: 1.3 | C27: Blaze Shield II | D27: Bolsas | E27: =+ROUNDUP(CUBICACION!R2,0) -> 823 | F27: 25000 | G27: =+F27*E27 -> 20575000 | H27: 0.03 | I27: =+(G27*H27)+G27 -> 21192250 | J27: =I27/$I$111 -> 0.55398505 | K27: =+I27/(1-$K$11) -> 32603462 | M27: Total | N27: =+N26 -> 1696.0064 | O27: =+SUM(O24:O26) -> 0.84988234 | P27: =+I19 -> 1441.4059
B28: 1.4 | C28: Quik Set | D28: tineta | E28: =+ROUNDUP(E25/19,0) -> 0 | F28: =21.5*G11*1.5 -> 31605 | G28: =+F28*E28 -> 0 | H28: 0.05 | I28: =+(G28*H28)+G28 -> 0 | J28: =I28/$I$111 -> 0 | K28: =+I28/(1-$K$11) -> 0
B29: 1.5 | C29: MALLA | D29: M2 | E29: 0 | F29: =32967/50 -> 659.34 | G29: =+F29*E29 -> 0 | H29: 0.05 | I29: =+(G29*H29)+G29 -> 0 | J29: =I29/$I$111 -> 0 | K29: =+I29/(1-$K$11) -> 0
B30: 1.6 | C30: Bond Seal | D30: tineta | E30: =ROUNDUP(+(E27/4)*2/19,0) -> 22 | F30: 35000 | G30: =+F30*E30 -> 770000 | H30: 0.05 | I30: =+(G30*H30)+G30 -> 808500 | J30: =I30/$I$111 -> 0.021134939 | K30: =+I30/(1-$K$11) -> 1243846.2
B31: 1.7 | C31: SHIPPING | D31: UNI. | E31: 0 | F31: =4500*G11 -> 4410000 | G31: =+F31*E31 -> 0 | H31: 0.05 | I31: =+(G31*H31)+G31 -> 0 | J31: =I31/$I$111 -> 0 | K31: =+I31/(1-$K$11) -> 0
L32: BLAZE SHIELD II | M32: Descripción | N32: Superficie m2 | O32: UF/m2 | P32: Total P.U. (UF) | Q32: =+I27/($I$25+$I$26+$I$27) -> 1
B33: 2 | C33: MANO DE OBRA INDIRECTA | D33: =SUM(J34:J37) -> 0.047547731 | M33: Materiales Directos | N33: =+N36 -> 1696.0064 | O33: =+P33/N33 -> 0.48878432 | P33: =+Q32*P24 -> 828.98133 | Q33: =+E27/($E$25+$E$26+$E$27) -> 1
B34: 2.1 | C34: HD Instalacion de Faena | D34: HD | E34: 1 | I34: =+(G34*H34)+G34 -> 0 | J34: =I34/$I$111 -> 0 | K34: =+I34/(1-$K$13) -> 0 | M34: Mano de obra Directa e Indirecta | N34: =+N36 -> 1696.0064 | O34: =+P34/N34 -> 0.10262454 | P34: =+Q33*P25 -> 174.05188
B35: 2.2 | C35: HD induccion | D35: HD | E35: 1 | I35: =+(G35*H35)+G35 -> 0 | J35: =I35/$I$111 -> 0 | K35: =+I35/(1-$K$13) -> 0 | M35: Gastos Generales | N35: =+N36 -> 1696.0064 | O35: =+P35/N35 -> 0.25847348 | P35: =+Q33*P26 -> 438.37267
B36: 2.3 | C36: Supervisión 100% tiempo efectivo | D36: HD | E36: =+ROUNDUP((($E$25/$C$15+$E$26/$C$15+$E$27/$C$13)/$E$41)+$E$34+$E$35,0) -> 21 | F36: =75900 -> 75900 | G36: =+F36*E36 -> 1593900 | I36: =+(G36*H36)+G36 -> 1593900 | J36: =I36/$I$111 -> 0.041666022 | K36: =+I36/(1-$K$13) -> 2452153.8 | M36: Total | N36: =+CUBICACION!Q2 -> 1696.0064 | O36: =+SUM(O33:O35) -> 0.84988234 | P36: =+SUM(P33:P35) -> 1441.4059
B37: 2.4 | C37: Prevencionista 15% tiempo efectivo | D37: HD | E37: 3 | F37: 75000 | G37: =+F37*E37 -> 225000 | I37: =+(G37*H37)+G37 -> 225000 | J37: =I37/$I$111 -> 0.0058817084 | K37: =+I37/(1-$K$13) -> 346153.85 | L37: CAFCO 400
M38: Descripción | N38: Superficie m2 | O38: UF/m2 | P38: Total P.U. (UF) | Q38: =+I26/($I$25+$I$26+$I$27) -> 0
C39: DURACIÓN OBRA | D39: HD | E39: =+ROUNDUP((($E$25/$C$15+$E$26/$C$15+$E$27/$C$13)/$E$41)+$E$34+$E$35,0) -> 21 | M39: Materiales Directos | N39: =+N42 -> 0 | O39: =+P39/N39 -> #DIV/0! | P39: =+Q38*P24 -> 0 | Q39: =+E26/($E$25+$E$26+$E$27) -> 0
M40: Mano de obra Directa e Indirecta | N40: =+N42 -> 0 | O40: =+P40/N40 -> #DIV/0! | P40: =+Q39*P25 -> 0
B41: 3 | C41: MANO DE OBRA DIRECTA | D41: =SUM(J42:J46) -> 0.073203743 | E41: 1 | F41: Cantidad de equipos | H41: 0.05 | I41: Fondo de reserva | M41: Gastos Generales | N41: =+N42 -> 0 | O41: =+P41/N41 -> #DIV/0! | P41: =+Q39*P26 -> 0
B42: 3.1 | C42: Aplicadores | D42: HD | E42: =ROUNDUP($E$36,0) -> 21 | F42: 45000 | G42: =+F42*E42*$E$41 -> 945000 | H42: =+$H$41 -> 0.05 | I42: =+(G42*H42)+G42 -> 992250 | J42: =I42/$I$111 -> 0.025938334 | K42: =+I42/(1-$K$15) -> 1526538.5 | L42: CAFCO 300 | M42: Total | N42: =+CUBICACION!Q3 -> 0 | O42: =+SUM(O39:O41) -> #DIV/0! | P42: =+SUM(P39:P41) -> 0
B43: 3.3 | C43: Maquinistas | D43: HD | E43: =ROUNDUP($E$36,0) -> 21 | F43: 42000 | G43: =+F43*E43*$E$41 -> 882000 | H43: =+$H$41 -> 0.05 | I43: =+(G43*H43)+G43 -> 926100 | J43: =I43/$I$111 -> 0.024209112 | K43: =+I43/(1-$K$15) -> 1424769.2
B44: 3.5 | C44: Ayudante de Aplicador | D44: HD | E44: =ROUNDUP($E$36,0) -> 21 | F44: 40000 | G44: =+F44*E44*$E$41 -> 840000 | H44: =+$H$41 -> 0.05 | I44: =+(G44*H44)+G44 -> 882000 | J44: =I44/$I$111 -> 0.023056297 | K44: =+I44/(1-$K$15) -> 1356923.1 | M44: Descripción | N44: Superficie m2 | O44: UF/m2 | P44: Total P.U. (UF) | Q44: =+I25/($I$25+$I$26+$I$27) -> 0
B45: 3.7 | C45: Mallero | D45: HD | F45: =33000 -> 33000 | G45: =+F45*E45*$E$41 -> 0 | H45: =+$H$41 -> 0.05 | I45: =+(G45*H45)+G45 -> 0 | J45: =I45/$I$111 -> 0 | K45: =+I45/(1-$K$15) -> 0 | M45: Materiales Directos | N45: =+N48 -> 0 | O45: =+P45/N45 -> #DIV/0! | P45: =+Q44*P24 -> 0 | Q45: =+E25/($E$25+$E$26+$E$27) -> 0
B46: 3.9 | C46: Pintor SBK 113 | D46: HD | E46: 0 | F46: 40000 | G46: =+F46*E46*$E$41 -> 0 | H46: =+$H$41 -> 0.05 | I46: =+(G46*H46)+G46 -> 0 | J46: =I46/$I$111 -> 0 | K46: =+I46/(1-$K$15) -> 0 | M46: Mano de obra Directa e Indirecta | N46: =+N48 -> 0 | O46: =+P46/N46 -> #DIV/0! | P46: =+Q45*P25 -> 0
...

Sheet COT. F.CONTROL
B2: PRESUPUESTO: | C2: F-30
B3: OBRA: | C3: TORRE KENNEDY
B4: PRODUCTO: | C4: PINTURA INTUMESCENTE
B5: ING. A CARGO:
N6: EN ANDAMIOS SE REQUIERE 100M2 DISPONIBLES DIARIAMENTE
B7: RESUMEN | F7: RESUMEN ECONIMICO | N7: SE CONSIDERA DAR CAPAS DE 325 CAPAS POR CADA MANO, POR LO TANTO EN CADA POSCICION SE OCUPARAN LOS ANDAMIOS 4 DIAS
I8: =+I19/C9 -> 2.3106811 | J8: uf/m2 | N8: SI LA APLICACIÓN DE P.I SE DEBE APLICAR CON RODILLO PARA EVITAR CONTAMINACION DR RDTRUCUTS , ESTA SE DEBE ENTREGAR LIMPIA, ES DECIR SIN POLVO NI GRASAS
B9: SUPERFICIE 1 | C9: =+SUM(CUBICACION!U2:U6) -> 1877.384 | D9: m2 | F9: VALOR UF | G9: 40830 | H9: $ | I9: =+G19/C9 -> 94345.111 | J9: $/m2
B11: Superficie Topping | C11: 0 | D11: m2 | F11: VALOR DOLLAR | G11: 919.07 | H11: $ | K11: 0.15 | L11: Margen mat
B13: Rendimiento m2/día | C13: 0 | D13: m2/día | F13: COSTO | G13: =+I139 -> 1.3856968e+08 | H13: $ | I13: =+G13/G9 -> 3393.8202 | J13: UF | K13: 0.35 | L13: Margen MOI | O13: 703.2 | P13: 0.898 | Q13: =P13*O13 -> 631.4736
C15: 5 | D15: Tineta/máquina | F15: MARGEN DE VENTA | G15: =+L140 -> 0.21765971 | H15: % | I15: =+G15 -> 0.21765971 | J15: % | K15: 0.35 | L15: Margen MOD | P15: 0.52 | Q15: =P15*O13 -> 365.664
B17: Cantidad de equipos | C17: 2 | D17: Unidad | F17: MARGEN DE VENTA | G17: =+G19-G13 -> 38552324 | H17: $ | I17: =+G17/G9 -> 944.21563 | J17: UF | K17: 0.35 | L17: Margen Equipos | P17: 0.071 | Q17: =P17*O13 -> 49.9272
F19: PRECIO DE VENTA | G19: =+L139 -> 1.77122e+08 | H19: $ | I19: =+G19/G9 -> 4338.0358 | J19: UF | K19: 0.35 | L19: Margen GG | P19: =P13+P15+P17 -> 1.489 | Q19: =Q13+Q15+Q17 -> 1047.0648
Q21: =O13*P19 -> 1047.0648
B22: ÍTEM Nº | C22: Descripcion | D22: Unidad | E22: Cantidad | F22: Costo Unitario | G22: Costo Total | H22: PERDIDA (%) | I22: Costo Total C/Perdida | J22: INCIDENCIA (%) | K22: Margen (%) | L22: Precio de Venta | N22: CUADRO GENERAL
N23: Descripción | O23: Superficie m² | P23: UF/m² | Q23: Total P.U (UF) | R23: %
B24: 1 | C24: MATERIALES | D24: =SUM(J25:J29) -> 0.71892785 | F24: Actualizados Febrero '25 | N24: Materiales Directos | O24: =+$C$9 -> 1877.384 | P24: =+Q24/O24 -> 1.661213 | Q24: =+R24*Q27 -> 3118.7347 | R24: =+D24 -> 0.71892785
B25: 1.1 | C25: Fire Control | D25: Tinetas | E25: =+CUBICACION!V2 -> 0 | F25: 115000 | G25: =+F25*E25 -> 0 | H25: 0.05 | I25: =+(G25*H25)+G25 -> 0 | J25: =I25/$I$139 -> 0 | K25: =$K$11 -> 0.15 | L25: =+I25/(1-K25) -> 0 | N25: Mano de obra Directa e Indirecta | O25: =$C$9 -> 1877.384 | P25: =+Q25/O25 -> 0.29574086 | Q25: =+R25*Q27 -> 555.21916 | R25: =+D31+F40 -> 0.12798861
B26: 1.2 | C26: Fire Tex 5062 | D26: Tinetas | E26: =+CUBICACION!V3 -> 0 | F26: 163000 | G26: =F26*E26 -> 0 | H26: 0.05 | I26: =+(G26*H26)+G26 -> 0 | J26: =I26/$I$139 -> 0 | K26: =$K$11 -> 0.15 | L26: =+I26/(1-K26) -> 0 | N26: Gastos Generales | O26: =$C$9 -> 1877.384 | P26: =+Q26/O26 -> 0.35372726 | Q26: =+R26*Q27 -> 664.08189 | R26: =+D65+D77+D89+D102+D109+D117+D124+D136 -> 0.15308354
B27: 1.3 | C27: Fire Tex 5090 | D27: Tinetas | E27: =+CUBICACION!V4 -> 496 | F27: 195000 | G27: =F27*E27 -> 96720000 | H27: 0.03 | I27: =+(G27*H27)+G27 -> 99621600 | J27: =I27/$I$139 -> 0.71892785 | K27: =$K$11 -> 0.15 | L27: =+I27/(1-K27) -> 1.1720188e+08 | N27: Total | O27: =+O26 -> 1877.384 | P27: =+SUM(P24:P26) -> 2.3106811 | Q27: =+I19 -> 4338.0358
B28: 1.4 | C28: Fire Tex 5120 | D28: Tinetas | E28: =+CUBICACION!V5 -> 0 | F28: 195000 | G28: =F28*E28 -> 0 | H28: 0.03 | I28: =+(G28*H28)+G28 -> 0 | J28: =I28/$I$139 -> 0 | K28: =$K$11 -> 0.15 | L28: =+I28/(1-K28) -> 0
B29: 1.5 | C29: Topping | D29: Tinetas | G29: =F29*E29 -> 0 | H29: 0.05 | I29: =+(G29*H29)+G29 -> 0 | J29: =I29/$I$139 -> 0 | K29: =$K$11 -> 0.15 | L29: =+I29/(1-K29) -> 0
N30: Fire Control
B31: 2 | C31: MANO DE OBRA INDIRECTA | D31: =SUM(J32:J38) -> 0.038860017 | N31: Descripción | O31: Superficie m² | P31: UF/m² | Q31: Total P.U (UF) | R31: =+$E$25/($E$25+$E$26) -> #DIV/0!
B32: 2.1 | C32: HD Instalacion/retiro de Faena | D32: HD | E32: 1 | H32: 0.05 | I32: =+(G32*H32)+G32 -> 0 | J32: =I32/$I$139 -> 0 | K32: =+$K$13 -> 0.35 | L32: =+I32/(1-K32) -> 0 | N32: Materiales Directos | O32: =+$O$35 -> 0 | P32: =+Q32/O32 -> #DIV/0! | Q32: =+Q24*$R$31 -> #DIV/0!
B33: 2.2 | C33: HD induccion | D33: HD | E33: 1 | H33: 0.05 | I33: =+(G33*H33)+G33 -> 0 | J33: =I33/$I$139 -> 0 | K33: =+$K$13 -> 0.35 | L33: =+I33/(1-K33) -> 0 | N33: Mano de obra Directa e Indirecta | O33: =$O$35 -> 0 | P33: =+Q33/O33 -> #DIV/0! | Q33: =+Q25*$R$31 -> #DIV/0!
B34: 2.3 | C34: Supervisión 100% tiempo efectivo | D34: HD | E34: =+ROUNDUP(E38,0)*1 -> 52 | F34: =74000*1.3 -> 96200 | G34: =+F34*E34 -> 5002400 | H34: 0.05 | I34: =+(G34*H34)+G34 -> 5252520 | J34: =I34/$I$139 -> 0.037905263 | K34: =+$K$13 -> 0.35 | L34: =+I34/(1-K34) -> 8080800 | N34: Gastos Generales | O34: =$O$35 -> 0 | P34: =+Q34/O34 -> #DIV/0! | Q34: =+Q26*$R$31 -> #DIV/0!
B35: 2.4 | C35: Prevencionista 100% tiempo efectivo | D35: HD | E35: 3 | F35: 42000 | G35: =+F35*E35 -> 126000 | H35: 0.05 | I35: =+(G35*H35)+G35 -> 132300 | J35: =I35/$I$139 -> 0.00095475433 | K35: =+$K$13 -> 0.35 | L35: =+I35/(1-K35) -> 203538.46 | N35: Total | O35: =+CUBICACION!U2 -> 0 | P35: =+SUM(P32:P34) -> #DIV/0! | Q35: =+SUM(Q32:Q34) -> #DIV/0!
B36: 2.5 | C36: Administrador /oficina técnica | D36: HD | E36: 0 | F36: =62500+26000 -> 88500 | G36: =+F36*E36 -> 0 | H36: 0.05 | I36: =+(G36*H36)+G36 -> 0 | J36: =I36/$I$139 -> 0 | K36: =+$K$13 -> 0.35 | L36: =+I36/(1-K36) -> 0
C38: Duracion obra | D38: HD | E38: =+ROUNDUP(($E$25+$E$26+$E$27+$E$28+$E$29)/($C$15*$C$17),0)+$E$32+$E$33 -> 52 | N38: Fire Tex
N39: Descripción | O39: Superficie m² | P39: UF/m² | Q39: Total P.U (UF) | R39: =+$E$26/($E$25+$E$26) -> #DIV/0!
B40: 3 | C40: MANO DE OBRA DIRECTA | D40: cantidad de equipos | F40: =SUM(J41:J63) -> 0.08912859 | G40: fondo de reserva | H40: 0.05 | N40: Materiales Directos | O40: =+$O$43 -> 0 | P40: =+Q40/O40 -> #DIV/0! | Q40: =+R39*Q24 -> #DIV/0!
B41: SUBCONTRATO 2 | C41: Aplicador | D41: HD | E41: =$E$38 -> 52 | F41: =45000*1.3*$C$17 -> 117000 | G41: =+F41*E41 -> 6084000 | H41: =+H40 -> 0.05 | I41: =+(G41*H41)+G41 -> 6388200 | J41: =I41/$I$139 -> 0.046100995 | K41: =+K15 -> 0.35 | L41: =+I41/(1-K41) -> 9828000 | N41: Mano de obra Directa e Indirecta | O41: =+$O$43 -> 0 | P41: =+Q41/O41 -> #DIV/0! | Q41: =+R39*Q25 -> #DIV/0!
C42: Ayudante | D42: HD | E42: =$E$38 -> 52 | F42: =42000*1.3*$C$17 -> 109200 | G42: =+F42*E42 -> 5678400 | H42: =+H40 -> 0.05 | I42: =+(G42*H42)+G42 -> 5962320 | J42: =I42/$I$139 -> 0.043027595 | K42: =+K15 -> 0.35 | L42: =+I42/(1-K42) -> 9172800 | N42: Gastos Generales | O42: =+$O$43 -> 0 | P42: =+Q42/O42 -> #DIV/0! | Q42: =+R39*Q27 -> #DIV/0!
C43: Maquinista | D43: HD | E43: 0 | F43: =33000 -> 33000 | G43: =+F43*E43 -> 0 | H43: =+H40 -> 0.05 | I43: =+(G43*H43)+G43 -> 0 | J43: =I43/$I$139 -> 0 | K43: =+K15 -> 0.35 | L43: =+I43/(1-K43) -> 0 | N43: Total | O43: =CUBICACION!U3 -> 0 | P43: =+SUM(P40:P42) -> #DIV/0! | Q43: =+SUM(Q40:Q42) -> #DIV/0!
C44: mallero | D44: HD | E44: 0 | F44: =28000 -> 28000 | G44: =+F44*E44 -> 0 | H44: =+H40 -> 0.05 | I44: =+(G44*H44)+G44 -> 0 | J44: =I44/$I$139 -> 0 | K44: =+K15 -> 0.35 | L44: =+I44/(1-K44) -> 0
C45: Variable HH | D45: HD | E45: 0 | G45: =+F45*E45 -> 0 | H45: =+H40 -> 0.05 | I45: =+(G45*H45)+G45 -> 0 | J45: =I45/$I$139 -> 0 | K45: =+K15 -> 0.35 | L45: =+I45/(1-K45) -> 0
B46: 2.6 | C46: ="Instalación Pintura SUB-CONTRATO ("&E46&" personas)" -> Instalación Pintura SUB-CONTRATO (4 personas) | D46: N° | E46: =2*C17 -> 4
B47: 2.6.0 | D47: M2 | G47: =+F47*E47 -> 0 | H47: 0.05 | I47: =+(G47*H47)+G47 -> 0 | J47: =I47/$I$139 -> 0 | K47: =+$K$13 -> 0.35 | L47: =+I47/(1-K47) -> 0
B48: 2.6.1 | D48: M2 | G48: =+F48*E48 -> 0 | H48: 0.05 | I48: =+(G48*H48)+G48 -> 0 | J48: =I48/$I$139 -> 0 | K48: =+$K$13 -> 0.35 | L48: =+I48/(1-K48) -> 0
...

Sheet resumen
A3: ESTRUCTURA | B3: DIMENSIONES | C3: RESIST. AL FUEGO | D3: MASIV. (M-1) | E3: CARAS EXPTAS. | F3: MATERIAL | G3: Suma de ÁREA EXPUESTA [m2]
A4: ARRIOSTRAMINETO VERTICAL | B4: 100X100X3 | C4: F-60 | D4: 333 | E4: 4 | F4: Fire Tex 5090 | G4: 150.32
A5: COSTANERA | B5: 125X50X15X2 | C5: 60 | D5: 1057 | E5: 3 | F5: Blaze Shield II | G5: 1161.7348
A6: LOSA | B6: - | C6: 60 | D6: - | E6: 1 | F6: Blaze Shield II | G6: 328.581
A7: PILAR | B7: 100X100X3 | C7: F-60 | D7: 333 | E7: 4 | F7: Fire Tex 5090 | G7: 6.2
A8: PILAR | B8: 150X150X5 | C8: F-60 | D8: 200 | E8: 4 | F8: Fire Tex 5090 | G8: 114.96
A9: PILAR | B9: 200X100X3 | C9: F-60 | D9: 333 | E9: 4 | F9: Fire Tex 5090 | G9: 20.16
A10: PILAR | B10: 200X100X4 | C10: F-60 | D10: 250 | E10: 4 | F10: Fire Tex 5090 | G10: 51.18
A11: PILAR | B11: MM 400X200X4 | C11: F-60 | D11: 236 | E11: 4 | F11: Fire Tex 5090 | G11: 326.4
A12: PUNTAL | B12: 100X100X3 | C12: F-60 | D12: 333 | E12: 4 | F12: Fire Tex 5090 | G12: 77.928
A13: VIGA | B13: M1 MM600X225X4 | C13: F-60 | D13: 250 | E13: 4 | F13: Fire Tex 5090 | G13: 891
A14: VIGA | B14: 100X100X3 | C14: F-60 | D14: 333 | E14: 4 | F14: Fire Tex 5090 | G14: 54.712
A15: VIGA | B15: 200X100X3 | C15: F-60 | D15: 333 | E15: 4 | F15: Fire Tex 5090 | G15: 13.644
A16: VIGA | B16: 200X100X4 | C16: F-60 | D16: 250 | E16: 4 | F16: Fire Tex 5090 | G16: 2.4
A17: VIGA | B17: M1 MM400X200X4 | C17: F-60 | D17: 236 | E17: 4 | F17: Fire Tex 5090 | G17: 168.48
A18: VIGA BAJO LOSA | B18: 200X100X8,5X5,6 | C18: 60 | D18: 265 | E18: 3 | F18: Blaze Shield II | G18: 145.0873
A19: VIGA BAJO LOSA | B19: 240X120X9,8X6,2 | C19: 60 | D19: 233 | E19: 3 | F19: Blaze Shield II | G19: 60.6033
A20: (en blanco) | B20: (en blanco) | C20: (en blanco) | D20: (en blanco) | E20: 4 | F20: (en blanco) | G20: 0
A21: Total general | G21: 3573.3904
A24: ESTRUCTURA | B24: DIMENSIONES | C24: RESIST. AL FUEGO | D24: MASIV. (M-1) | E24: CARAS EXPTAS. | F24: MATERIAL | G24: ÁREA EXPUESTA [m2] | H24: COMENTARIO
A25: ARRIOSTRAMINETO VERTICAL | B25: 100X100X3 | C25: F-60 | D25: 333 | E25: 4 | F25: Fire Tex 5090 | G25: 150.32 | H25: CERTIFICABLE
A26: COSTANERA | B26: 125X50X15X2 | C26: F-60 | D26: 1057 | E26: 3 | F26: Blaze Shield II | G26: 1161.7348 | H26: CERTIFICABLE
A27: LOSA | B27: - | C27: F-60 | D27: - | E27: 1 | F27: Blaze Shield II | G27: 328.581 | H27: CERTIFICABLE
A28: PILAR | B28: 100X100X3 | C28: F-60 | D28: 333 | E28: 4 | F28: Fire Tex 5090 | G28: 6.2 | H28: CERTIFICABLE
A29: PILAR | B29: 150X150X5 | C29: F-60 | D29: 200 | E29: 4 | F29: Fire Tex 5090 | G29: 114.96 | H29: CERTIFICABLE
A30: PILAR | B30: 200X100X3 | C30: F-60 | D30: 333 | E30: 4 | F30: Fire Tex 5090 | G30: 20.16 | H30: CERTIFICABLE
A31: PILAR | B31: 200X100X4 | C31: F-60 | D31: 250 | E31: 4 | F31: Fire Tex 5090 | G31: 51.18 | H31: CERTIFICABLE
A32: PILAR | B32: MM 400X200X4 | C32: F-60 | D32: 236 | E32: 4 | F32: Fire Tex 5090 | G32: 326.4 | H32: CERTIFICABLE
A33: PUNTAL | B33: 100X100X3 | C33: F-60 | D33: 333 | E33: 4 | F33: Fire Tex 5090 | G33: 77.928 | H33: CERTIFICABLE
A34: VIGA | B34: M1 MM600X225X4 | C34: F-60 | D34: 250 | E34: 4 | F34: Fire Tex 5090 | G34: 891 | H34: CERTIFICABLE
A35: VIGA | B35: 100X100X3 | C35: F-60 | D35: 333 | E35: 4 | F35: Fire Tex 5090 | G35: 54.712 | H35: CERTIFICABLE
A36: VIGA | B36: 200X100X3 | C36: F-60 | D36: 333 | E36: 4 | F36: Fire Tex 5090 | G36: 13.644 | H36: CERTIFICABLE
A37: VIGA | B37: 200X100X4 | C37: F-60 | D37: 250 | E37: 4 | F37: Fire Tex 5090 | G37: 2.4 | H37: CERTIFICABLE
A38: VIGA | B38: M1 MM400X200X4 | C38: F-60 | D38: 236 | E38: 4 | F38: Fire Tex 5090 | G38: 168.48 | H38: CERTIFICABLE
A39: VIGA BAJO LOSA | B39: 200X100X8,5X5,6 | C39: F-60 | D39: 265 | E39: 3 | F39: Blaze Shield II | G39: 145.0873 | H39: CERTIFICABLE
A40: VIGA BAJO LOSA | B40: 240X120X9,8X6,2 | C40: F-60 | D40: 233 | E40: 3 | F40: Blaze Shield II | G40: 60.6033 | H40: CERTIFICABLE
A41: Total general | G41: 3573.3904

Sheet CUBICACION
P1: Material | Q1: M2 | R1: Total bolsas | T1: Material | U1: M2 | V1: Total tinetas
P2: Blaze Shield II | Q2: =+SUMIF($O$9:$O$1620,P2,$N$9:$N$1620) -> 1696.0064 | R2: =+ROUNDUP(SUMIF($O$9:$O$1620,P2,$U$9:$U$1620),0) -> 823 | T2: Fire Control | U2: =(SUMIF($O$9:$O$1620,T2,$N$9:$N$1620)) -> 0 | V2: =ROUNDUP(SUMIF($O$9:$O$1620,T2,$S$9:$S$1620),0) -> 0
P3: Cafco 400 | Q3: =+SUMIF($O$9:$O$1620,P3,$N$9:$N$1620) -> 0 | R3: =+ROUNDUP(SUMIF($O$9:$O$1620,P3,$U$9:$U$1620),0) -> 0 | T3: Fire Tex 5062 | U3: =(SUMIF($O$9:$O$1620,T3,$N$9:$N$1620)) -> 0 | V3: =ROUNDUP(SUMIF($O$9:$O$1620,T3,$S$9:$S$1620),0) -> 0
P4: Cafco 300 | Q4: =+SUMIF($O$9:$O$1620,P4,$N$9:$N$1620) -> 0 | R4: =+ROUNDUP(SUMIF($O$9:$O$1620,P4,$U$9:$U$1620),0) -> 0 | T4: Fire Tex 5090 | U4: =(SUMIF($O$9:$O$1620,T4,$N$9:$N$1620)) -> 1877.384 | V4: =ROUNDUP(SUMIF($O$9:$O$1620,T4,$S$9:$S$1620),0) -> 496
T5: Fire Tex 5120 | U5: =(SUMIF($O$9:$O$1620,T5,$N$9:$N$1620)) -> 0 | V5: =ROUNDUP(SUMIF($O$9:$O$1620,T5,$S$9:$S$1620),0) -> 0
N6: TOTAL | Q6: MAX
N7: =SUM(N9:N1620) -> 3573.3904 | Q7: =MAX(Q9:Q1620) -> 2828
A8: UBICACIÓN | B8: PLANO | C8: DESCRIPCIÓN EN PLANO | D8: ESTRUCTURA | E8: DIMENSIONES | F8: PERFIL | G8: CANT. | H8: CANTIDAD ESTRUCTURAS | I8: LARGO [mm] | J8: CARAS EXPTAS. | K8: PERÍMETRO EXPUESTO [mm] | L8: RESIST. AL FUEGO | M8: MASIV. (M-1) | N8: ÁREA EXPUESTA [m2] | O8: MATERIAL | P8: CERTIFICACION | Q8: MICRAS | R8: FORMULA | S8: TINETAS | T8: ESPESOR (mm) | U8: SACOS | V8: ANOTACIONES
A9: ELEVACION EJE A | B9: 107-B | C9: PM1 | D9: PILAR | E9: MM 400X200X4 | F9: CJ | G9: 2 | H9: 1 | I9: 5000 | J9: 4 | K9: 1200 | L9: F-60 | M9: 236 | N9: =+IF(F9="","",(K9*I9*H9*G9)/1000000) -> 12 | O9: Fire Tex 5090 | P9: Software Idiem | Q9: =+IF(OR(O9="Fire Control",O9="Fire Tex 5062",O9="Fire Tex 5090",O9="Fire Tex 5120"),'CALCULO PINTURA'!P10," ") -> 2196 | R9: =+IF(OR(O9="Fire Control",O9="Fire Tex 5062",O9="Fire Tex 5090",O9="Fire Tex 5120"),'CALCULO PINTURA'!R10," ") -> 4.0077949 | S9: =+IF(OR(O9="Fire Control",O9="Fire Tex 5062",O9="Fire Tex 5090",O9="Fire Tex 5120"),'CALCULO PINTURA'!S10," ") -> 2.9941652 | T9: =+IF(OR(O9="Blaze Shield II",O9="Cafco 400",O9="Cafco 300"),'CALCULO MORTERO'!N10," ") | U9: =+IF(OR(O9="Blaze Shield II",O9="Cafco 400",O9="Cafco 300"),'CALCULO MORTERO'!O10," ") | V9: {=_xlfn.IFS(O9="Blaze Shield II",'CALCULO MORTERO'!P10, O9="Cafco 400",'CALCULO MORTERO'!Q10,O9="Cafco 300",'CALCULO MORTERO'!S10, AND(OR(O9="Fire tex 5090", O9="Fire Tex 5062", O9="Fire Tex 5120", O9="Fire Control"),Q9>0), "CERT.",TRUE,"-")} -> CERT. | AM9: Blaze Shield II | AO9: Software Idiem
A10: ELEVACION EJE A | B10: 107-B | C10: PM1 | D10: PILAR | E10: MM 400X200X4 | F10: CJ | G10: 10 | H10: 1 | I10: 6000 | J10: 4 | K10: 1200 | L10: F-60 | M10: 236 | N10: =+IF(F10="","",(K10*I10*H10*G10)/1000000) -> 72 | O10: Fire Tex 5090 | P10: Software Idiem | Q10: =+IF(OR(O10="Fire Control",O10="Fire Tex 5062",O10="Fire Tex 5090",O10="Fire Tex 5120"),'CALCULO PINTURA'!P11," ") -> 2196 | R10: =+IF(OR(O10="Fire Control",O10="Fire Tex 5062",O10="Fire Tex 5090",O10="Fire Tex 5120"),'CALCULO PINTURA'!R11," ") -> 4.0077949 | S10: =+IF(OR(O10="Fire Control",O10="Fire Tex 5062",O10="Fire Tex 5090",O10="Fire Tex 5120"),'CALCULO PINTURA'!S11," ") -> 17.964991 | T10: =+IF(OR(O10="Blaze Shield II",O10="Cafco 400",O10="Cafco 300"),'CALCULO MORTERO'!N11," ") | U10: =+IF(OR(O10="Blaze Shield II",O10="Cafco 400",O10="Cafco 300"),'CALCULO MORTERO'!O11," ") | V10: {=_xlfn.IFS(O10="Blaze Shield II",'CALCULO MORTERO'!P11, O10="Cafco 400",'CALCULO MORTERO'!Q11,O10="Cafco 300",'CALCULO MORTERO'!S11, AND(OR(O10="Fire tex 5090", O10="Fire Tex 5062", O10="Fire Tex 5120", O10="Fire Control"),Q10>0), "CERT.",TRUE,"-")} -> CERT. | AM10: Cafco 400 | AO10: Ensayo Idiem
A11: ELEVACION EJE A | B11: 107-B | C11: PM3 | D11: PILAR | E11: 150X150X5 | F11: CJ | G11: 4 | H11: 1 | I11: 4000 | J11: 4 | K11: 600 | L11: F-60 | M11: 200 | N11: =+IF(F11="","",(K11*I11*H11*G11)/1000000) -> 9.6 | O11: Fire Tex 5090 | P11: Software Idiem | Q11: =+IF(OR(O11="Fire Control",O11="Fire Tex 5062",O11="Fire Tex 5090",O11="Fire Tex 5120"),'CALCULO PINTURA'!P12," ") -> 1930 | R11: =+IF(OR(O11="Fire Control",O11="Fire Tex 5062",O11="Fire Tex 5090",O11="Fire Tex 5120"),'CALCULO PINTURA'!R12," ") -> 4.5601646 | S11: =+IF(OR(O11="Fire Control",O11="Fire Tex 5062",O11="Fire Tex 5090",O11="Fire Tex 5120"),'CALCULO PINTURA'!S12," ") -> 2.1051872 | T11: =+IF(OR(O11="Blaze Shield II",O11="Cafco 400",O11="Cafco 300"),'CALCULO MORTERO'!N12," ") | U11: =+IF(OR(O11="Blaze Shield II",O11="Cafco 400",O11="Cafco 300"),'CALCULO MORTERO'!O12," ") | V11: {=_xlfn.IFS(O11="Blaze Shield II",'CALCULO MORTERO'!P12, O11="Cafco 400",'CALCULO MORTERO'!Q12,O11="Cafco 300",'CALCULO MORTERO'!S12, AND(OR(O11="Fire tex 5090", O11="Fire Tex 5062", O11="Fire Tex 5120", O11="Fire Control"),Q11>0), "CERT.",TRUE,"-")} -> CERT. | AM11: Cafco 300
A12: ELEVACION EJE A | B12: 107-B | C12: CJ200X100X3 | D12: PILAR | E12: 200X100X3 | F12: CJ | G12: 2 | H12: 1 | I12: 6200 | J12: 4 | K12: 600 | L12: F-60 | M12: 333 | N12: =+IF(F12="","",(K12*I12*H12*G12)/1000000) -> 7.44 | O12: Fire Tex 5090 | P12: Software Idiem | Q12: =+IF(OR(O12="Fire Control",O12="Fire Tex 5062",O12="Fire Tex 5090",O12="Fire Tex 5120"),'CALCULO PINTURA'!P13," ") -> 2828 | R12: =+IF(OR(O12="Fire Control",O12="Fire Tex 5062",O12="Fire Tex 5090",O12="Fire Tex 5120"),'CALCULO PINTURA'!R13," ") -> 3.1121349 | S12: =+IF(OR(O12="Fire Control",O12="Fire Tex 5062",O12="Fire Tex 5090",O12="Fire Tex 5120"),'CALCULO PINTURA'!S13," ") -> 2.3906418 | T12: =+IF(OR(O12="Blaze Shield II",O12="Cafco 400",O12="Cafco 300"),'CALCULO MORTERO'!N13," ") | U12: =+IF(OR(O12="Blaze Shield II",O12="Cafco 400",O12="Cafco 300"),'CALCULO MORTERO'!O13," ") | V12: {=_xlfn.IFS(O12="Blaze Shield II",'CALCULO MORTERO'!P13, O12="Cafco 400",'CALCULO MORTERO'!Q13,O12="Cafco 300",'CALCULO MORTERO'!S13, AND(OR(O12="Fire tex 5090", O12="Fire Tex 5062", O12="Fire Tex 5120", O12="Fire Control"),Q12>0), "CERT.",TRUE,"-")} -> CERT. | AM12: Fire Control
A13: ELEVACION EJE A | B13: 107-B | C13: PUNTAL. TIP | D13: PUNTAL | E13: 100X100X3 | F13: CJ | G13: 1 | H13: 1 | I13: 68200 | J13: 4 | K13: 400 | L13: F-60 | M13: 333 | N13: =+IF(F13="","",(K13*I13*H13*G13)/1000000) -> 27.28 | O13: Fire Tex 5090 | P13: Software Idiem | Q13: =+IF(OR(O13="Fire Control",O13="Fire Tex 5062",O13="Fire Tex 5090",O13="Fire Tex 5120"),'CALCULO PINTURA'!P14," ") -> 2828 | R13: =+IF(OR(O13="Fire Control",O13="Fire Tex 5062",O13="Fire Tex 5090",O13="Fire Tex 5120"),'CALCULO PINTURA'!R14," ") -> 3.1121349 | S13: =+IF(OR(O13="Fire Control",O13="Fire Tex 5062",O13="Fire Tex 5090",O13="Fire Tex 5120"),'CALCULO PINTURA'!S14," ") -> 8.7656868 | T13: =+IF(OR(O13="Blaze Shield II",O13="Cafco 400",O13="Cafco 300"),'CALCULO MORTERO'!N14," ") | U13: =+IF(OR(O13="Blaze Shield II",O13="Cafco 400",O13="Cafco 300"),'CALCULO MORTERO'!O14," ") | V13: {=_xlfn.IFS(O13="Blaze Shield II",'CALCULO MORTERO'!P14, O13="Cafco 400",'CALCULO MORTERO'!Q14,O13="Cafco 300",'CALCULO MORTERO'!S14, AND(OR(O13="Fire tex 5090", O13="Fire Tex 5062", O13="Fire Tex 5120", O13="Fire Control"),Q13>0), "CERT.",TRUE,"-")} -> CERT. | AM13: Fire Tex 5120
A14: ELEVACION EJE A | B14: 107-B | C14: ARRIOSTRA | D14: ARRIOSTRAMINETO VERTICAL | E14: 100X100X3 | F14: CJ | G14: 8 | H14: 1 | I14: 7500 | J14: 4 | K14: 400 | L14: F-60 | M14: 333 | N14: =+IF(F14="","",(K14*I14*H14*G14)/1000000) -> 24 | O14: Fire Tex 5090 | P14: Software Idiem | Q14: =+IF(OR(O14="Fire Control",O14="Fire Tex 5062",O14="Fire Tex 5090",O14="Fire Tex 5120"),'CALCULO PINTURA'!P15," ") -> 2828 | R14: =+IF(OR(O14="Fire Control",O14="Fire Tex 5062",O14="Fire Tex 5090",O14="Fire Tex 5120"),'CALCULO PINTURA'!R15," ") -> 3.1121349 | S14: =+IF(OR(O14="Fire Control",O14="Fire Tex 5062",O14="Fire Tex 5090",O14="Fire Tex 5120"),'CALCULO PINTURA'!S15," ") -> 7.7117479 | T14: =+IF(OR(O14="Blaze Shield II",O14="Cafco 400",O14="Cafco 300"),'CALCULO MORTERO'!N15," ") | U14: =+IF(OR(O14="Blaze Shield II",O14="Cafco 400",O14="Cafco 300"),'CALCULO MORTERO'!O15," ") | V14: {=_xlfn.IFS(O14="Blaze Shield II",'CALCULO MORTERO'!P15, O14="Cafco 400",'CALCULO MORTERO'!Q15,O14="Cafco 300",'CALCULO MORTERO'!S15, AND(OR(O14="Fire tex 5090", O14="Fire Tex 5062", O14="Fire Tex 5120", O14="Fire Control"),Q14>0), "CERT.",TRUE,"-")} -> CERT. | AM14: Fire Tex 5090
A15: ELEVACION EJE F | B15: 107-B | C15: PM1 | D15: PILAR | E15: MM 400X200X4 | F15: CJ | G15: 2 | H15: 1 | I15: 5000 | J15: 4 | K15: 1200 | L15: F-60 | M15: 236 | N15: =+IF(F15="","",(K15*I15*H15*G15)/1000000) -> 12 | O15: Fire Tex 5090 | P15: Software Idiem | Q15: =+IF(OR(O15="Fire Control",O15="Fire Tex 5062",O15="Fire Tex 5090",O15="Fire Tex 5120"),'CALCULO PINTURA'!P16," ") -> 2196 | R15: =+IF(OR(O15="Fire Control",O15="Fire Tex 5062",O15="Fire Tex 5090",O15="Fire Tex 5120"),'CALCULO PINTURA'!R16," ") -> 4.0077949 | S15: =+IF(OR(O15="Fire Control",O15="Fire Tex 5062",O15="Fire Tex 5090",O15="Fire Tex 5120"),'CALCULO PINTURA'!S16," ") -> 2.9941652 | T15: =+IF(OR(O15="Blaze Shield II",O15="Cafco 400",O15="Cafco 300"),'CALCULO MORTERO'!N16," ") | U15: =+IF(OR(O15="Blaze Shield II",O15="Cafco 400",O15="Cafco 300"),'CALCULO MORTERO'!O16," ") | V15: {=_xlfn.IFS(O15="Blaze Shield II",'CALCULO MORTERO'!P16, O15="Cafco 400",'CALCULO MORTERO'!Q16,O15="Cafco 300",'CALCULO MORTERO'!S16, AND(OR(O15="Fire tex 5090", O15="Fire Tex 5062", O15="Fire Tex 5120", O15="Fire Control"),Q15>0), "CERT.",TRUE,"-")} -> CERT. | AM15: Fire Tex 5062
A16: ELEVACION EJE F | B16: 107-B | C16: PM1 | D16: PILAR | E16: MM 400X200X4 | F16: CJ | G16: 10 | H16: 1 | I16: 6000 | J16: 4 | K16: 1200 | L16: F-60 | M16: 236 | N16: =+IF(F16="","",(K16*I16*H16*G16)/1000000) -> 72 | O16: Fire Tex 5090 | P16: Software Idiem | Q16: =+IF(OR(O16="Fire Control",O16="Fire Tex 5062",O16="Fire Tex 5090",O16="Fire Tex 5120"),'CALCULO PINTURA'!P17," ") -> 2196 | R16: =+IF(OR(O16="Fire Control",O16="Fire Tex 5062",O16="Fire Tex 5090",O16="Fire Tex 5120"),'CALCULO PINTURA'!R17," ") -> 4.0077949 | S16: =+IF(OR(O16="Fire Control",O16="Fire Tex 5062",O16="Fire Tex 5090",O16="Fire Tex 5120"),'CALCULO PINTURA'!S17," ") -> 17.964991 | T16: =+IF(OR(O16="Blaze Shield II",O16="Cafco 400",O16="Cafco 300"),'CALCULO MORTERO'!N17," ") | U16: =+IF(OR(O16="Blaze Shield II",O16="Cafco 400",O16="Cafco 300"),'CALCULO MORTERO'!O17," ") | V16: {=_xlfn.IFS(O16="Blaze Shield II",'CALCULO MORTERO'!P17, O16="Cafco 400",'CALCULO MORTERO'!Q17,O16="Cafco 300",'CALCULO MORTERO'!S17, AND(OR(O16="Fire tex 5090", O16="Fire Tex 5062", O16="Fire Tex 5120", O16="Fire Control"),Q16>0), "CERT.",TRUE,"-")} -> CERT.
A17: ELEVACION EJE F | B17: 107-B | C17: PM3 | D17: PILAR | E17: 150X150X5 | F17: CJ | G17: 2 | H17: 1 | I17: 4000 | J17: 4 | K17: 600 | L17: F-60 | M17: 200 | N17: =+IF(F17="","",(K17*I17*H17*G17)/1000000) -> 4.8 | O17: Fire Tex 5090 | P17: Software Idiem | Q17: =+IF(OR(O17="Fire Control",O17="Fire Tex 5062",O17="Fire Tex 5090",O17="Fire Tex 5120"),'CALCULO PINTURA'!P18," ") -> 1930 | R17: =+IF(OR(O17="Fire Control",O17="Fire Tex 5062",O17="Fire Tex 5090",O17="Fire Tex 5120"),'CALCULO PINTURA'!R18," ") -> 4.5601646 | S17: =+IF(OR(O17="Fire Control",O17="Fire Tex 5062",O17="Fire Tex 5090",O17="Fire Tex 5120"),'CALCULO PINTURA'!S18," ") -> 1.0525936 | T17: =+IF(OR(O17="Blaze Shield II",O17="Cafco 400",O17="Cafco 300"),'CALCULO MORTERO'!N18," ") | U17: =+IF(OR(O17="Blaze Shield II",O17="Cafco 400",O17="Cafco 300"),'CALCULO MORTERO'!O18," ") | V17: {=_xlfn.IFS(O17="Blaze Shield II",'CALCULO MORTERO'!P18, O17="Cafco 400",'CALCULO MORTERO'!Q18,O17="Cafco 300",'CALCULO MORTERO'!S18, AND(OR(O17="Fire tex 5090", O17="Fire Tex 5062", O17="Fire Tex 5120", O17="Fire Control"),Q17>0), "CERT.",TRUE,"-")} -> CERT.
A18: ELEVACION EJE F | B18: 107-B | C18: CJ200X100X3 | D18: PILAR | E18: 200X100X3 | F18: CJ | G18: 1 | H18: 1 | I18: 6200 | J18: 4 | K18: 600 | L18: F-60 | M18: 333 | N18: =+IF(F18="","",(K18*I18*H18*G18)/1000000) -> 3.72 | O18: Fire Tex 5090 | P18: Software Idiem | Q18: =+IF(OR(O18="Fire Control",O18="Fire Tex 5062",O18="Fire Tex 5090",O18="Fire Tex 5120"),'CALCULO PINTURA'!P19," ") -> 2828 | R18: =+IF(OR(O18="Fire Control",O18="Fire Tex 5062",O18="Fire Tex 5090",O18="Fire Tex 5120"),'CALCULO PINTURA'!R19," ") -> 3.1121349 | S18: =+IF(OR(O18="Fire Control",O18="Fire Tex 5062",O18="Fire Tex 5090",O18="Fire Tex 5120"),'CALCULO PINTURA'!S19," ") -> 1.1953209 | T18: =+IF(OR(O18="Blaze Shield II",O18="Cafco 400",O18="Cafco 300"),'CALCULO MORTERO'!N19," ") | U18: =+IF(OR(O18="Blaze Shield II",O18="Cafco 400",O18="Cafco 300"),'CALCULO MORTERO'!O19," ") | V18: {=_xlfn.IFS(O18="Blaze Shield II",'CALCULO MORTERO'!P19, O18="Cafco 400",'CALCULO MORTERO'!Q19,O18="Cafco 300",'CALCULO MORTERO'!S19, AND(OR(O18="Fire tex 5090", O18="Fire Tex 5062", O18="Fire Tex 5120", O18="Fire Control"),Q18>0), "CERT.",TRUE,"-")} -> CERT.
A19: ELEVACION EJE F | B19: 107-B | C19: PUNTAL. TIP | D19: PUNTAL | E19: 100X100X3 | F19: CJ | G19: 1 | H19: 1 | I19: 68200 | J19: 4 | K19: 400 | L19: F-60 | M19: 333 | N19: =+IF(F19="","",(K19*I19*H19*G19)/1000000) -> 27.28 | O19: Fire Tex 5090 | P19: Software Idiem | Q19: =+IF(OR(O19="Fire Control",O19="Fire Tex 5062",O19="Fire Tex 5090",O19="Fire Tex 5120"),'CALCULO PINTURA'!P20," ") -> 2828 | R19: =+IF(OR(O19="Fire Control",O19="Fire Tex 5062",O19="Fire Tex 5090",O19="Fire Tex 5120"),'CALCULO PINTURA'!R20," ") -> 3.1121349 | S19: =+IF(OR(O19="Fire Control",O19="Fire Tex 5062",O19="Fire Tex 5090",O19="Fire Tex 5120"),'CALCULO PINTURA'!S20," ") -> 8.7656868 | T19: =+IF(OR(O19="Blaze Shield II",O19="Cafco 400",O19="Cafco 300"),'CALCULO MORTERO'!N20," ") | U19: =+IF(OR(O19="Blaze Shield II",O19="Cafco 400",O19="Cafco 300"),'CALCULO MORTERO'!O20," ") | V19: {=_xlfn.IFS(O19="Blaze Shield II",'CALCULO MORTERO'!P20, O19="Cafco 400",'CALCULO MORTERO'!Q20,O19="Cafco 300",'CALCULO MORTERO'!S20, AND(OR(O19="Fire tex 5090", O19="Fire Tex 5062", O19="Fire Tex 5120", O19="Fire Control"),Q19>0), "CERT.",TRUE,"-")} -> CERT.
A20: ELEVACION EJE F | B20: 107-B | C20: ARRIOSTRA | D20: ARRIOSTRAMINETO VERTICAL | E20: 100X100X3 | F20: CJ | G20: 8 | H20: 1 | I20: 7500 | J20: 4 | K20: 400 | L20: F-60 | M20: 333 | N20: =+IF(F20="","",(K20*I20*H20*G20)/1000000) -> 24 | O20: Fire Tex 5090 | P20: Software Idiem | Q20: =+IF(OR(O20="Fire Control",O20="Fire Tex 5062",O20="Fire Tex 5090",O20="Fire Tex 5120"),'CALCULO PINTURA'!P21," ") -> 2828 | R20: =+IF(OR(O20="Fire Control",O20="Fire Tex 5062",O20="Fire Tex 5090",O20="Fire Tex 5120"),'CALCULO PINTURA'!R21," ") -> 3.1121349 | S20: =+IF(OR(O20="Fire Control",O20="Fire Tex 5062",O20="Fire Tex 5090",O20="Fire Tex 5120"),'CALCULO PINTURA'!S21," ") -> 7.7117479 | T20: =+IF(OR(O20="Blaze Shield II",O20="Cafco 400",O20="Cafco 300"),'CALCULO MORTERO'!N21," ") | U20: =+IF(OR(O20="Blaze Shield II",O20="Cafco 400",O20="Cafco 300"),'CALCULO MORTERO'!O21," ") | V20: {=_xlfn.IFS(O20="Blaze Shield II",'CALCULO MORTERO'!P21, O20="Cafco 400",'CALCULO MORTERO'!Q21,O20="Cafco 300",'CALCULO MORTERO'!S21, AND(OR(O20="Fire tex 5090", O20="Fire Tex 5062", O20="Fire Tex 5120", O20="Fire Control"),Q20>0), "CERT.",TRUE,"-")} -> CERT.
A21: ELEVACION EJE B | B21: 107-B | C21: PM2 | D21: PILAR | E21: 200X100X4 | F21: CJ | G21: 2 | H21: 1 | I21: 7500 | J21: 4 | K21: 600 | L21: F-60 | M21: 250 | N21: =+IF(F21="","",(K21*I21*H21*G21)/1000000) -> 9 | O21: Fire Tex 5090 | P21: Software Idiem | Q21: =+IF(OR(O21="Fire Control",O21="Fire Tex 5062",O21="Fire Tex 5090",O21="Fire Tex 5120"),'CALCULO PINTURA'!P22," ") -> 2262 | R21: =+IF(OR(O21="Fire Control",O21="Fire Tex 5062",O21="Fire Tex 5090",O21="Fire Tex 5120"),'CALCULO PINTURA'!R22," ") -> 3.8908566 | S21: =+IF(OR(O21="Fire Control",O21="Fire Tex 5062",O21="Fire Tex 5090",O21="Fire Tex 5120"),'CALCULO PINTURA'!S22," ") -> 2.3131153 | T21: =+IF(OR(O21="Blaze Shield II",O21="Cafco 400",O21="Cafco 300"),'CALCULO MORTERO'!N22," ") | U21: =+IF(OR(O21="Blaze Shield II",O21="Cafco 400",O21="Cafco 300"),'CALCULO MORTERO'!O22," ") | V21: {=_xlfn.IFS(O21="Blaze Shield II",'CALCULO MORTERO'!P22, O21="Cafco 400",'CALCULO MORTERO'!Q22,O21="Cafco 300",'CALCULO MORTERO'!S22, AND(OR(O21="Fire tex 5090", O21="Fire Tex 5062", O21="Fire Tex 5120", O21="Fire Control"),Q21>0), "CERT.",TRUE,"-")} -> CERT.
A22: ELEVACION EJE B | B22: 107-B | C22: PM3 | D22: PILAR | E22: 150X150X5 | F22: CJ | G22: 9 | H22: 1 | I22: 6400 | J22: 4 | K22: 600 | L22: F-60 | M22: 200 | N22: =+IF(F22="","",(K22*I22*H22*G22)/1000000) -> 34.56 | O22: Fire Tex 5090 | P22: Software Idiem | Q22: =+IF(OR(O22="Fire Control",O22="Fire Tex 5062",O22="Fire Tex 5090",O22="Fire Tex 5120"),'CALCULO PINTURA'!P23," ") -> 1930 | R22: =+IF(OR(O22="Fire Control",O22="Fire Tex 5062",O22="Fire Tex 5090",O22="Fire Tex 5120"),'CALCULO PINTURA'!R23," ") -> 4.5601646 | S22: =+IF(OR(O22="Fire Control",O22="Fire Tex 5062",O22="Fire Tex 5090",O22="Fire Tex 5120"),'CALCULO PINTURA'!S23," ") -> 7.5786739 | T22: =+IF(OR(O22="Blaze Shield II",O22="Cafco 400",O22="Cafco 300"),'CALCULO MORTERO'!N23," ") | U22: =+IF(OR(O22="Blaze Shield II",O22="Cafco 400",O22="Cafco 300"),'CALCULO MORTERO'!O23," ") | V22: {=_xlfn.IFS(O22="Blaze Shield II",'CALCULO MORTERO'!P23, O22="Cafco 400",'CALCULO MORTERO'!Q23,O22="Cafco 300",'CALCULO MORTERO'!S23, AND(OR(O22="Fire tex 5090", O22="Fire Tex 5062", O22="Fire Tex 5120", O22="Fire Control"),Q22>0), "CERT.",TRUE,"-")} -> CERT.
A23: ELEVACION EJE B | B23: 107-B | C23: PM3 | D23: PILAR | E23: 150X150X5 | F23: CJ | G23: 3 | H23: 1 | I23: 7500 | J23: 4 | K23: 600 | L23: F-60 | M23: 200 | N23: =+IF(F23="","",(K23*I23*H23*G23)/1000000) -> 13.5 | O23: Fire Tex 5090 | P23: Software Idiem | Q23: =+IF(OR(O23="Fire Control",O23="Fire Tex 5062",O23="Fire Tex 5090",O23="Fire Tex 5120"),'CALCULO PINTURA'!P24," ") -> 1930 | R23: =+IF(OR(O23="Fire Control",O23="Fire Tex 5062",O23="Fire Tex 5090",O23="Fire Tex 5120"),'CALCULO PINTURA'!R24," ") -> 4.5601646 | S23: =+IF(OR(O23="Fire Control",O23="Fire Tex 5062",O23="Fire Tex 5090",O23="Fire Tex 5120"),'CALCULO PINTURA'!S24," ") -> 2.9604195 | T23: =+IF(OR(O23="Blaze Shield II",O23="Cafco 400",O23="Cafco 300"),'CALCULO MORTERO'!N24," ") | U23: =+IF(OR(O23="Blaze Shield II",O23="Cafco 400",O23="Cafco 300"),'CALCULO MORTERO'!O24," ") | V23: {=_xlfn.IFS(O23="Blaze Shield II",'CALCULO MORTERO'!P24, O23="Cafco 400",'CALCULO MORTERO'!Q24,O23="Cafco 300",'CALCULO MORTERO'!S24, AND(OR(O23="Fire tex 5090", O23="Fire Tex 5062", O23="Fire Tex 5120", O23="Fire Control"),Q23>0), "CERT.",TRUE,"-")} -> CERT.
J24: 4 | N24: 0 | P24: Software Idiem | Q24: =+IF(OR(O24="Fire Control",O24="Fire Tex 5062",O24="Fire Tex 5090",O24="Fire Tex 5120"),'CALCULO PINTURA'!P25," ") | R24: =+IF(OR(O24="Fire Control",O24="Fire Tex 5062",O24="Fire Tex 5090",O24="Fire Tex 5120"),'CALCULO PINTURA'!R25," ") | S24: =+IF(OR(O24="Fire Control",O24="Fire Tex 5062",O24="Fire Tex 5090",O24="Fire Tex 5120"),'CALCULO PINTURA'!S25," ") | T24: =+IF(OR(O24="Blaze Shield II",O24="Cafco 400",O24="Cafco 300"),'CALCULO MORTERO'!N25," ") | U24: =+IF(OR(O24="Blaze Shield II",O24="Cafco 400",O24="Cafco 300"),'CALCULO MORTERO'!O25," ") | V24: {=_xlfn.IFS(O24="Blaze Shield II",'CALCULO MORTERO'!P25, O24="Cafco 400",'CALCULO MORTERO'!Q25,O24="Cafco 300",'CALCULO MORTERO'!S25, AND(OR(O24="Fire tex 5090", O24="Fire Tex 5062", O24="Fire Tex 5120", O24="Fire Control"),Q24>0), "CERT.",TRUE,"-")} -> -
J25: 4 | N25: 0 | P25: Software Idiem | Q25: =+IF(OR(O25="Fire Control",O25="Fire Tex 5062",O25="Fire Tex 5090",O25="Fire Tex 5120"),'CALCULO PINTURA'!P26," ") | R25: =+IF(OR(O25="Fire Control",O25="Fire Tex 5062",O25="Fire Tex 5090",O25="Fire Tex 5120"),'CALCULO PINTURA'!R26," ") | S25: =+IF(OR(O25="Fire Control",O25="Fire Tex 5062",O25="Fire Tex 5090",O25="Fire Tex 5120"),'CALCULO PINTURA'!S26," ") | T25: =+IF(OR(O25="Blaze Shield II",O25="Cafco 400",O25="Cafco 300"),'CALCULO MORTERO'!N26," ") | U25: =+IF(OR(O25="Blaze Shield II",O25="Cafco 400",O25="Cafco 300"),'CALCULO MORTERO'!O26," ") | V25: {=_xlfn.IFS(O25="Blaze Shield II",'CALCULO MORTERO'!P26, O25="Cafco 400",'CALCULO MORTERO'!Q26,O25="Cafco 300",'CALCULO MORTERO'!S26, AND(OR(O25="Fire tex 5090", O25="Fire Tex 5062", O25="Fire Tex 5120", O25="Fire Control"),Q25>0), "CERT.",TRUE,"-")} -> -
A26: ELEVACION EJE 10 | B26: 106-B | C26: M1 MM600X225X4 | D26: VIGA | E26: M1 MM600X225X4 | F26: CJ | G26: 2 | H26: 1 | I26: 15000 | J26: 4 | K26: 1650 | L26: F-60 | M26: 250 | N26: =+IF(F26="","",(K26*I26*H26*G26)/1000000) -> 49.5 | O26: Fire Tex 5090 | P26: Software Idiem | Q26: =+IF(OR(O26="Fire Control",O26="Fire Tex 5062",O26="Fire Tex 5090",O26="Fire Tex 5120"),'CALCULO PINTURA'!P27," ") -> 2262 | R26: =+IF(OR(O26="Fire Control",O26="Fire Tex 5062",O26="Fire Tex 5090",O26="Fire Tex 5120"),'CALCULO PINTURA'!R27," ") -> 3.8908566 | S26: =+IF(OR(O26="Fire Control",O26="Fire Tex 5062",O26="Fire Tex 5090",O26="Fire Tex 5120"),'CALCULO PINTURA'!S27," ") -> 12.722134 | T26: =+IF(OR(O26="Blaze Shield II",O26="Cafco 400",O26="Cafco 300"),'CALCULO MORTERO'!N27," ") | U26: =+IF(OR(O26="Blaze Shield II",O26="Cafco 400",O26="Cafco 300"),'CALCULO MORTERO'!O27," ") | V26: {=_xlfn.IFS(O26="Blaze Shield II",'CALCULO MORTERO'!P27, O26="Cafco 400",'CALCULO MORTERO'!Q27,O26="Cafco 300",'CALCULO MORTERO'!S27, AND(OR(O26="Fire tex 5090", O26="Fire Tex 5062", O26="Fire Tex 5120", O26="Fire Control"),Q26>0), "CERT.",TRUE,"-")} -> CERT.
A27: ELEVACION EJE 11 | B27: 106-B | C27: M1 MM600X225X4 | D27: VIGA | E27: M1 MM600X225X4 | F27: CJ | G27: 2 | H27: 1 | I27: 15000 | J27: 4 | K27: 1650 | L27: F-60 | M27: 250 | N27: =+IF(F27="","",(K27*I27*H27*G27)/1000000) -> 49.5 | O27: Fire Tex 5090 | P27: Software Idiem | Q27: =+IF(OR(O27="Fire Control",O27="Fire Tex 5062",O27="Fire Tex 5090",O27="Fire Tex 5120"),'CALCULO PINTURA'!P28," ") -> 2262 | R27: =+IF(OR(O27="Fire Control",O27="Fire Tex 5062",O27="Fire Tex 5090",O27="Fire Tex 5120"),'CALCULO PINTURA'!R28," ") -> 3.8908566 | S27: =+IF(OR(O27="Fire Control",O27="Fire Tex 5062",O27="Fire Tex 5090",O27="Fire Tex 5120"),'CALCULO PINTURA'!S28," ") -> 12.722134 | T27: =+IF(OR(O27="Blaze Shield II",O27="Cafco 400",O27="Cafco 300"),'CALCULO MORTERO'!N28," ") | U27: =+IF(OR(O27="Blaze Shield II",O27="Cafco 400",O27="Cafco 300"),'CALCULO MORTERO'!O28," ") | V27: {=_xlfn.IFS(O27="Blaze Shield II",'CALCULO MORTERO'!P28, O27="Cafco 400",'CALCULO MORTERO'!Q28,O27="Cafco 300",'CALCULO MORTERO'!S28, AND(OR(O27="Fire tex 5090", O27="Fire Tex 5062", O27="Fire Tex 5120", O27="Fire Control"),Q27>0), "CERT.",TRUE,"-")} -> CERT.
A28: ELEVACION EJE 02 | B28: 106-B | C28: M1 MM600X225X4 | D28: VIGA | E28: M1 MM600X225X4 | F28: CJ | G28: 2 | H28: 1 | I28: 15000 | J28: 4 | K28: 1650 | L28: F-60 | M28: 250 | N28: =+IF(F28="","",(K28*I28*H28*G28)/1000000) -> 49.5 | O28: Fire Tex 5090 | P28: Software Idiem | Q28: =+IF(OR(O28="Fire Control",O28="Fire Tex 5062",O28="Fire Tex 5090",O28="Fire Tex 5120"),'CALCULO PINTURA'!P29," ") -> 2262 | R28: =+IF(OR(O28="Fire Control",O28="Fire Tex 5062",O28="Fire Tex 5090",O28="Fire Tex 5120"),'CALCULO PINTURA'!R29," ") -> 3.8908566 | S28: =+IF(OR(O28="Fire Control",O28="Fire Tex 5062",O28="Fire Tex 5090",O28="Fire Tex 5120"),'CALCULO PINTURA'!S29," ") -> 12.722134 | T28: =+IF(OR(O28="Blaze Shield II",O28="Cafco 400",O28="Cafco 300"),'CALCULO MORTERO'!N29," ") | U28: =+IF(OR(O28="Blaze Shield II",O28="Cafco 400",O28="Cafco 300"),'CALCULO MORTERO'!O29," ") | V28: {=_xlfn.IFS(O28="Blaze Shield II",'CALCULO MORTERO'!P29, O28="Cafco 400",'CALCULO MORTERO'!Q29,O28="Cafco 300",'CALCULO MORTERO'!S29, AND(OR(O28="Fire tex 5090", O28="Fire Tex 5062", O28="Fire Tex 5120", O28="Fire Control"),Q28>0), "CERT.",TRUE,"-")} -> CERT.
A29: ELEVACION EJES 3, 4, 5, 6, 7,8 , 9 | B29: 106-B | C29: M1 MM600X225X4 | D29: VIGA | E29: M1 MM600X225X4 | F29: CJ | G29: 2 | H29: 7 | I29: 15000 | J29: 4 | K29: 1650 | L29: F-60 | M29: 250 | N29: =+IF(F29="","",(K29*I29*H29*G29)/1000000) -> 346.5 | O29: Fire Tex 5090 | P29: Software Idiem | Q29: =+IF(OR(O29="Fire Control",O29="Fire Tex 5062",O29="Fire Tex 5090",O29="Fire Tex 5120"),'CALCULO PINTURA'!P30," ") -> 2262 | R29: =+IF(OR(O29="Fire Control",O29="Fire Tex 5062",O29="Fire Tex 5090",O29="Fire Tex 5120"),'CALCULO PINTURA'!R30," ") -> 3.8908566 | S29: =+IF(OR(O29="Fire Control",O29="Fire Tex 5062",O29="Fire Tex 5090",O29="Fire Tex 5120"),'CALCULO PINTURA'!S30," ") -> 89.05494 | T29: =+IF(OR(O29="Blaze Shield II",O29="Cafco 400",O29="Cafco 300"),'CALCULO MORTERO'!N30," ") | U29: =+IF(OR(O29="Blaze Shield II",O29="Cafco 400",O29="Cafco 300"),'CALCULO MORTERO'!O30," ") | V29: {=_xlfn.IFS(O29="Blaze Shield II",'CALCULO MORTERO'!P30, O29="Cafco 400",'CALCULO MORTERO'!Q30,O29="Cafco 300",'CALCULO MORTERO'!S30, AND(OR(O29="Fire tex 5090", O29="Fire Tex 5062", O29="Fire Tex 5120", O29="Fire Control"),Q29>0), "CERT.",TRUE,"-")} -> CERT.
A30: ELEVACION EJE 12 | B30: 106-B | C30: M1 MM600X225X4 | D30: VIGA | E30: M1 MM600X225X4 | F30: CJ | G30: 2 | H30: 7 | I30: 15000 | J30: 4 | K30: 1650 | L30: F-60 | M30: 250 | N30: =+IF(F30="","",(K30*I30*H30*G30)/1000000) -> 346.5 | O30: Fire Tex 5090 | P30: Software Idiem | Q30: =+IF(OR(O30="Fire Control",O30="Fire Tex 5062",O30="Fire Tex 5090",O30="Fire Tex 5120"),'CALCULO PINTURA'!P31," ") -> 2262 | R30: =+IF(OR(O30="Fire Control",O30="Fire Tex 5062",O30="Fire Tex 5090",O30="Fire Tex 5120"),'CALCULO PINTURA'!R31," ") -> 3.8908566 | S30: =+IF(OR(O30="Fire Control",O30="Fire Tex 5062",O30="Fire Tex 5090",O30="Fire Tex 5120"),'CALCULO PINTURA'!S31," ") -> 89.05494 | T30: =+IF(OR(O30="Blaze Shield II",O30="Cafco 400",O30="Cafco 300"),'CALCULO MORTERO'!N31," ") | U30: =+IF(OR(O30="Blaze Shield II",O30="Cafco 400",O30="Cafco 300"),'CALCULO MORTERO'!O31," ") | V30: {=_xlfn.IFS(O30="Blaze Shield II",'CALCULO MORTERO'!P31, O30="Cafco 400",'CALCULO MORTERO'!Q31,O30="Cafco 300",'CALCULO MORTERO'!S31, AND(OR(O30="Fire tex 5090", O30="Fire Tex 5062", O30="Fire Tex 5120", O30="Fire Control"),Q30>0), "CERT.",TRUE,"-")} -> CERT.
A31: ELEVACION EJE 12 | B31: 106-B | C31: PM2 | D31: PILAR | E31: 200X100X4 | F31: CJ | G31: 2 | H31: 1 | I31: 6200 | J31: 4 | K31: 600 | L31: F-60 | M31: 250 | N31: =+IF(F31="","",(K31*I31*H31*G31)/1000000) -> 7.44 | O31: Fire Tex 5090 | P31: Software Idiem | Q31: =+IF(OR(O31="Fire Control",O31="Fire Tex 5062",O31="Fire Tex 5090",O31="Fire Tex 5120"),'CALCULO PINTURA'!P32," ") -> 2262 | R31: =+IF(OR(O31="Fire Control",O31="Fire Tex 5062",O31="Fire Tex 5090",O31="Fire Tex 5120"),'CALCULO PINTURA'!R32," ") -> 3.8908566 | S31: =+IF(OR(O31="Fire Control",O31="Fire Tex 5062",O31="Fire Tex 5090",O31="Fire Tex 5120"),'CALCULO PINTURA'!S32," ") -> 1.9121753 | T31: =+IF(OR(O31="Blaze Shield II",O31="Cafco 400",O31="Cafco 300"),'CALCULO MORTERO'!N32," ") | U31: =+IF(OR(O31="Blaze Shield II",O31="Cafco 400",O31="Cafco 300"),'CALCULO MORTERO'!O32," ") | V31: {=_xlfn.IFS(O31="Blaze Shield II",'CALCULO MORTERO'!P32, O31="Cafco 400",'CALCULO MORTERO'!Q32,O31="Cafco 300",'CALCULO MORTERO'!S32, AND(OR(O31="Fire tex 5090", O31="Fire Tex 5062", O31="Fire Tex 5120", O31="Fire Control"),Q31>0), "CERT.",TRUE,"-")} -> CERT.
A32: ELEVACION EJE 12 | B32: 106-B | C32: PM2 | D32: PILAR | E32: 200X100X4 | F32: CJ | G32: 1 | H32: 1 | I32: 7500 | J32: 4 | K32: 600 | L32: F-60 | M32: 250 | N32: =+IF(F32="","",(K32*I32*H32*G32)/1000000) -> 4.5 | O32: Fire Tex 5090 | P32: Software Idiem | Q32: =+IF(OR(O32="Fire Control",O32="Fire Tex 5062",O32="Fire Tex 5090",O32="Fire Tex 5120"),'CALCULO PINTURA'!P33," ") -> 2262 | R32: =+IF(OR(O32="Fire Control",O32="Fire Tex 5062",O32="Fire Tex 5090",O32="Fire Tex 5120"),'CALCULO PINTURA'!R33," ") -> 3.8908566 | S32: =+IF(OR(O32="Fire Control",O32="Fire Tex 5062",O32="Fire Tex 5090",O32="Fire Tex 5120"),'CALCULO PINTURA'!S33," ") -> 1.1565577 | T32: =+IF(OR(O32="Blaze Shield II",O32="Cafco 400",O32="Cafco 300"),'CALCULO MORTERO'!N33," ") | U32: =+IF(OR(O32="Blaze Shield II",O32="Cafco 400",O32="Cafco 300"),'CALCULO MORTERO'!O33," ") | V32: {=_xlfn.IFS(O32="Blaze Shield II",'CALCULO MORTERO'!P33, O32="Cafco 400",'CALCULO MORTERO'!Q33,O32="Cafco 300",'CALCULO MORTERO'!S33, AND(OR(O32="Fire tex 5090", O32="Fire Tex 5062", O32="Fire Tex 5120", O32="Fire Control"),Q32>0), "CERT.",TRUE,"-")} -> CERT.
A33: ELEVACION EJE 12 | B33: 106-B | C33: CJ200X100X3 | D33: PILAR | E33: 200X100X3 | F33: CJ | G33: 1 | H33: 1 | I33: 15000 | J33: 4 | K33: 600 | L33: F-60 | M33: 333 | N33: =+IF(F33="","",(K33*I33*H33*G33)/1000000) -> 9 | O33: Fire Tex 5090 | P33: Software Idiem | Q33: =+IF(OR(O33="Fire Control",O33="Fire Tex 5062",O33="Fire Tex 5090",O33="Fire Tex 5120"),'CALCULO PINTURA'!P34," ") -> 2828 | R33: =+IF(OR(O33="Fire Control",O33="Fire Tex 5062",O33="Fire Tex 5090",O33="Fire Tex 5120"),'CALCULO PINTURA'!R34," ") -> 3.1121349 | S33: =+IF(OR(O33="Fire Control",O33="Fire Tex 5062",O33="Fire Tex 5090",O33="Fire Tex 5120"),'CALCULO PINTURA'!S34," ") -> 2.8919055 | T33: =+IF(OR(O33="Blaze Shield II",O33="Cafco 400",O33="Cafco 300"),'CALCULO MORTERO'!N34," ") | U33: =+IF(OR(O33="Blaze Shield II",O33="Cafco 400",O33="Cafco 300"),'CALCULO MORTERO'!O34," ") | V33: {=_xlfn.IFS(O33="Blaze Shield II",'CALCULO MORTERO'!P34, O33="Cafco 400",'CALCULO MORTERO'!Q34,O33="Cafco 300",'CALCULO MORTERO'!S34, AND(OR(O33="Fire tex 5090", O33="Fire Tex 5062", O33="Fire Tex 5120", O33="Fire Control"),Q33>0), "CERT.",TRUE,"-")} -> CERT.
A34: ELEVACION EJE 12 | B34: 106-B | C34: PM3 | D34: PILAR | E34: 150X150X5 | F34: CJ | G34: 4 | H34: 1 | I34: 4000 | J34: 4 | K34: 600 | L34: F-60 | M34: 200 | N34: =+IF(F34="","",(K34*I34*H34*G34)/1000000) -> 9.6 | O34: Fire Tex 5090 | P34: Software Idiem | Q34: =+IF(OR(O34="Fire Control",O34="Fire Tex 5062",O34="Fire Tex 5090",O34="Fire Tex 5120"),'CALCULO PINTURA'!P35," ") -> 1930 | R34: =+IF(OR(O34="Fire Control",O34="Fire Tex 5062",O34="Fire Tex 5090",O34="Fire Tex 5120"),'CALCULO PINTURA'!R35," ") -> 4.5601646 | S34: =+IF(OR(O34="Fire Control",O34="Fire Tex 5062",O34="Fire Tex 5090",O34="Fire Tex 5120"),'CALCULO PINTURA'!S35," ") -> 2.1051872 | T34: =+IF(OR(O34="Blaze Shield II",O34="Cafco 400",O34="Cafco 300"),'CALCULO MORTERO'!N35," ") | U34: =+IF(OR(O34="Blaze Shield II",O34="Cafco 400",O34="Cafco 300"),'CALCULO MORTERO'!O35," ") | V34: {=_xlfn.IFS(O34="Blaze Shield II",'CALCULO MORTERO'!P35, O34="Cafco 400",'CALCULO MORTERO'!Q35,O34="Cafco 300",'CALCULO MORTERO'!S35, AND(OR(O34="Fire tex 5090", O34="Fire Tex 5062", O34="Fire Tex 5120", O34="Fire Control"),Q34>0), "CERT.",TRUE,"-")} -> CERT.
A35: ELEVACION EJE 1 | B35: 106-B | C35: PM2 | D35: PILAR | E35: 200X100X4 | F35: CJ | G35: 1 | H35: 1 | I35: 8000 | J35: 4 | K35: 600 | L35: F-60 | M35: 250 | N35: =+IF(F35="","",(K35*I35*H35*G35)/1000000) -> 4.8 | O35: Fire Tex 5090 | P35: Software Idiem | Q35: =+IF(OR(O35="Fire Control",O35="Fire Tex 5062",O35="Fire Tex 5090",O35="Fire Tex 5120"),'CALCULO PINTURA'!P36," ") -> 2262 | R35: =+IF(OR(O35="Fire Control",O35="Fire Tex 5062",O35="Fire Tex 5090",O35="Fire Tex 5120"),'CALCULO PINTURA'!R36," ") -> 3.8908566 | S35: =+IF(OR(O35="Fire Control",O35="Fire Tex 5062",O35="Fire Tex 5090",O35="Fire Tex 5120"),'CALCULO PINTURA'!S36," ") -> 1.2336615 | T35: =+IF(OR(O35="Blaze Shield II",O35="Cafco 400",O35="Cafco 300"),'CALCULO MORTERO'!N36," ") | U35: =+IF(OR(O35="Blaze Shield II",O35="Cafco 400",O35="Cafco 300"),'CALCULO MORTERO'!O36," ") | V35: {=_xlfn.IFS(O35="Blaze Shield II",'CALCULO MORTERO'!P36, O35="Cafco 400",'CALCULO MORTERO'!Q36,O35="Cafco 300",'CALCULO MORTERO'!S36, AND(OR(O35="Fire tex 5090", O35="Fire Tex 5062", O35="Fire Tex 5120", O35="Fire Control"),Q35>0), "CERT.",TRUE,"-")} -> CERT.
A36: ELEVACION EJE 1 | B36: 106-B | C36: PM2 | D36: PILAR | E36: 200X100X4 | F36: CJ | G36: 1 | H36: 1 | I36: 7500 | J36: 4 | K36: 600 | L36: F-60 | M36: 250 | N36: =+IF(F36="","",(K36*I36*H36*G36)/1000000) -> 4.5 | O36: Fire Tex 5090 | P36: Software Idiem | Q36: =+IF(OR(O36="Fire Control",O36="Fire Tex 5062",O36="Fire Tex 5090",O36="Fire Tex 5120"),'CALCULO PINTURA'!P37," ") -> 2262 | R36: =+IF(OR(O36="Fire Control",O36="Fire Tex 5062",O36="Fire Tex 5090",O36="Fire Tex 5120"),'CALCULO PINTURA'!R37," ") -> 3.8908566 | S36: =+IF(OR(O36="Fire Control",O36="Fire Tex 5062",O36="Fire Tex 5090",O36="Fire Tex 5120"),'CALCULO PINTURA'!S37," ") -> 1.1565577 | T36: =+IF(OR(O36="Blaze Shield II",O36="Cafco 400",O36="Cafco 300"),'CALCULO MORTERO'!N37," ") | U36: =+IF(OR(O36="Blaze Shield II",O36="Cafco 400",O36="Cafco 300"),'CALCULO MORTERO'!O37," ") | V36: {=_xlfn.IFS(O36="Blaze Shield II",'CALCULO MORTERO'!P37, O36="Cafco 400",'CALCULO MORTERO'!Q37,O36="Cafco 300",'CALCULO MORTERO'!S37, AND(OR(O36="Fire tex 5090", O36="Fire Tex 5062", O36="Fire Tex 5120", O36="Fire Control"),Q36>0), "CERT.",TRUE,"-")} -> CERT.
A37: ELEVACION EJE 1 | B37: 106-B | C37: PM2 | D37: PILAR | E37: 200X100X4 | F37: CJ | G37: 1 | H37: 1 | I37: 6500 | J37: 4 | K37: 600 | L37: F-60 | M37: 250 | N37: =+IF(F37="","",(K37*I37*H37*G37)/1000000) -> 3.9 | O37: Fire Tex 5090 | P37: Software Idiem | Q37: =+IF(OR(O37="Fire Control",O37="Fire Tex 5062",O37="Fire Tex 5090",O37="Fire Tex 5120"),'CALCULO PINTURA'!P38," ") -> 2262 | R37: =+IF(OR(O37="Fire Control",O37="Fire Tex 5062",O37="Fire Tex 5090",O37="Fire Tex 5120"),'CALCULO PINTURA'!R38," ") -> 3.8908566 | S37: =+IF(OR(O37="Fire Control",O37="Fire Tex 5062",O37="Fire Tex 5090",O37="Fire Tex 5120"),'CALCULO PINTURA'!S38," ") -> 1.00235 | T37: =+IF(OR(O37="Blaze Shield II",O37="Cafco 400",O37="Cafco 300"),'CALCULO MORTERO'!N38," ") | U37: =+IF(OR(O37="Blaze Shield II",O37="Cafco 400",O37="Cafco 300"),'CALCULO MORTERO'!O38," ") | V37: {=_xlfn.IFS(O37="Blaze Shield II",'CALCULO MORTERO'!P38, O37="Cafco 400",'CALCULO MORTERO'!Q38,O37="Cafco 300",'CALCULO MORTERO'!S38, AND(OR(O37="Fire tex 5090", O37="Fire Tex 5062", O37="Fire Tex 5120", O37="Fire Control"),Q37>0), "CERT.",TRUE,"-")} -> CERT.
... A43: ELEVACION EJA 9A | B43: 106-B | C43: PM3 | D43: PILAR | E43: 150X150X5 | F43: CJ | G43: 1 | H43: 1 | I43: 6500 | J43: 4 | K43: 600 | L43: F-60 | M43: 200 | N43: =+IF(F43="","",(K43*I43*H43*G43)/1000000) -> 3.9 | O43: Fire Tex 5090 | P43: Software Idiem | Q43: =+IF(OR(O43="Fire Control",O43="Fire Tex 5062",O43="Fire Tex 5090",O43="Fire Tex 5120"),'CALCULO PINTURA'!P44," ") -> 1930 | R43: =+IF(OR(O43="Fire Control",O43="Fire Tex 5062",O43="Fire Tex 5090",O43="Fire Tex 5120"),'CALCULO PINTURA'!R44," ") -> 4.5601646 | S43: =+IF(OR(O43="Fire Control",O43="Fire Tex 5062",O43="Fire Tex 5090",O43="Fire Tex 5120"),'CALCULO PINTURA'!S44," ") -> 0.85523229 | T43: =+IF(OR(O43="Blaze Shield II",O43="Cafco 400",O43="Cafco 300"),'CALCULO MORTERO'!N44," ") | U43: =+IF(OR(O43="Blaze Shield II",O43="Cafco 400",O43="Cafco 300"),'CALCULO MORTERO'!O44," ") | V43: {=_xlfn.IFS(O43="Blaze Shield II",'CALCULO MORTERO'!P44, O43="Cafco 400",'CALCULO MORTERO'!Q44,O43="Cafco 300",'CALCULO MORTERO'!S44, AND(OR(O43="Fire tex 5090", O43="Fire Tex 5062", O43="Fire Tex 5120", O43="Fire Control"),Q43>0), "CERT.",TRUE,"-")} -> CERT.
J44: 4 | N44: 0 | P44: Software Idiem | Q44: =+IF(OR(O44="Fire Control",O44="Fire Tex 5062",O44="Fire Tex 5090",O44="Fire Tex 5120"),'CALCULO PINTURA'!P45," ") | R44: =+IF(OR(O44="Fire Control",O44="Fire Tex 5062",O44="Fire Tex 5090",O44="Fire Tex 5120"),'CALCULO PINTURA'!R45," ") | S44: =+IF(OR(O44="Fire Control",O44="Fire Tex 5062",O44="Fire Tex 5090",O44="Fire Tex 5120"),'CALCULO PINTURA'!S45," ") | T44: =+IF(OR(O44="Blaze Shield II",O44="Cafco 400",O44="Cafco 300"),'CALCULO MORTERO'!N45," ") | U44: =+IF(OR(O44="Blaze Shield II",O44="Cafco 400",O44="Cafco 300"),'CALCULO MORTERO'!O45," ") | V44: {=_xlfn.IFS(O44="Blaze Shield II",'CALCULO MORTERO'!P45, O44="Cafco 400",'CALCULO MORTERO'!Q45,O44="Cafco 300",'CALCULO MORTERO'!S45, AND(OR(O44="Fire tex 5090", O44="Fire Tex 5062", O44="Fire Tex 5120", O44="Fire Control"),Q44>0), "CERT.",TRUE,"-")} -> -
J45: 4 | N45: 0 | P45: Software Idiem | Q45: =+IF(OR(O45="Fire Control",O45="Fire Tex 5062",O45="Fire Tex 5090",O45="Fire Tex 5120"),'CALCULO PINTURA'!P46," ") | R45: =+IF(OR(O45="Fire Control",O45="Fire Tex 5062",O45="Fire Tex 5090",O45="Fire Tex 5120"),'CALCULO PINTURA'!R46," ") | S45: =+IF(OR(O45="Fire Control",O45="Fire Tex 5062",O45="Fire Tex 5090",O45="Fire Tex 5120"),'CALCULO PINTURA'!S46," ") | T45: =+IF(OR(O45="Blaze Shield II",O45="Cafco 400",O45="Cafco 300"),'CALCULO MORTERO'!N46," ") | U45: =+IF(OR(O45="Blaze Shield II",O45="Cafco 400",O45="Cafco 300"),'CALCULO MORTERO'!O46," ") | V45: {=_xlfn.IFS(O45="Blaze Shield II",'CALCULO MORTERO'!P46, O45="Cafco 400",'CALCULO MORTERO'!Q46,O45="Cafco 300",'CALCULO MORTERO'!S46, AND(OR(O45="Fire tex 5090", O45="Fire Tex 5062", O45="Fire Tex 5120", O45="Fire Control"),Q45>0), "CERT.",TRUE,"-")} -> -
...

Sheet FIRE CONTROL
C2: MASIVIDAD m-1 | D2: RESISTENCIA AL FUEGO
D3: F15 | E3: F30 | F3: F60 | G3: F90
C4: 60 | D4: 400 | E4: 400 | F4: 700 | G4: 1300
C5: 70 | D5: 400 | E5: 400 | F5: 750 | G5: 1400
C6: 80 | D6: 400 | E6: 400 | F6: 800 | G6: 1450
C7: 90 | D7: 400 | E7: 400 | F7: 850 | G7: 1550
C8: 100 | D8: 400 | E8: 400 | F8: 850 | G8: 1650
C9: 110 | D9: 400 | E9: 400 | F9: 900 | G9: 1700
C10: 120 | D10: 400 | E10: 400 | F10: 950 | G10: 1800
C11: 130 | D11: 400 | E11: 400 | F11: 1000
C12: 140 | D12: 400 | E12: 400 | F12: 1050
C13: 150 | D13: 400 | E13: 450 | F13: 1100
C14: 160 | D14: 400 | E14: 450 | F14: 1100
C15: 170 | D15: 400 | E15: 500 | F15: 1150
C16: 180 | D16: 400 | E16: 500 | F16: 1200
C17: 190 | D17: 400 | E17: 500 | F17: 1250
C18: 200 | D18: 400 | E18: 550 | F18: 1300
C19: 210 | D19: 400 | E19: 550 | F19: 1300
C20: 220 | D20: 400 | E20: 550 | F20: 1350
C21: 230 | D21: 400 | E21: 600 | F21: 1400
C22: 240 | D22: 400 | E22: 600 | F22: 1450
... C32: 340 | D32: 400 | E32: 750 | F32: 1800
C33: 350 | D33: 400 | E33: 750
C34: 360 | D34: 400 | E34: 800
C35: 370 | D35: 450 | E35: 800
C36: 380 | D36: 450 | E36: 800
C37: 390 | D37: 450 | E37: 800

Sheet FIRE TEX 5062
B2: IN BAJO LOSA | G2: IN 4 CARAS | L2: CJ BAJO LOSA | Q2: CJ 4 CARAS
B3: [m-1] | C3: F-15 | D3: F-30 | E3: F-60 | F3: F-90 | G3: [m-1] | H3: F-15 | I3: F-30 | J3: F-60 | K3: F-90 | L3: [m-1] | M3: F-15 | N3: F-30 | O3: F-60 | P3: F-90 | Q3: [m-1] | R3: F-15 | S3: F-30 | T3: F-60 | U3: F-90
B4: 60 | C4: 181 | D4: 181 | E4: 197 | F4: 650 | G4: 60 | H4: 174 | I4: 174 | J4: 193 | K4: 567 | L4: 60 | M4: 192 | N4: 192 | O4: 209 | P4: 689 | Q4: 60 | R4: 185 | S4: 185 | T4: 205 | U4: 602
B5: 70 | C5: 181 | D5: 181 | E5: 219 | F5: 730 | G5: 70 | H5: 174 | I5: 174 | J5: 216 | K5: 592 | L5: 70 | M5: 194 | N5: 194 | O5: 235 | P5: 782 | Q5: 70 | R5: 187 | S5: 187 | T5: 232 | U5: 634
B6: 80 | C6: 181 | D6: 181 | E6: 241 | F6: 809 | G6: 80 | H6: 174 | I6: 174 | J6: 238 | K6: 617 | L6: 80 | M6: 196 | N6: 196 | O6: 261 | P6: 874 | Q6: 80 | R6: 188 | S6: 188 | T6: 258 | U6: 667
B7: 90 | C7: 181 | D7: 181 | E7: 263 | F7: 889 | G7: 90 | H7: 174 | I7: 174 | J7: 261 | K7: 643 | L7: 90 | M7: 198 | N7: 198 | O7: 287 | Q7: 90 | R7: 190 | S7: 190 | T7: 285 | U7: 701
B8: 100 | C8: 181 | D8: 181 | E8: 285 | G8: 100 | H8: 174 | I8: 174 | J8: 283 | K8: 668 | L8: 100 | M8: 200 | N8: 200 | O8: 314 | Q8: 100 | R8: 192 | S8: 192 | T8: 312 | U8: 735
B9: 110 | C9: 181 | D9: 181 | E9: 306 | G9: 110 | H9: 174 | I9: 174 | J9: 306 | K9: 693 | L9: 110 | M9: 201 | N9: 201 | O9: 340 | Q9: 110 | R9: 194 | S9: 194 | T9: 340 | U9: 770
B10: 120 | C10: 181 | D10: 181 | E10: 328 | G10: 120 | H10: 174 | I10: 174 | J10: 328 | K10: 718 | L10: 120 | M10: 203 | N10: 203 | O10: 368 | Q10: 120 | R10: 195 | S10: 195 | T10: 368 | U10: 805
B11: 130 | C11: 181 | D11: 181 | E11: 350 | G11: 130 | H11: 174 | I11: 174 | J11: 351 | K11: 743 | L11: 130 | M11: 205 | N11: 205 | O11: 396 | Q11: 130 | R11: 197 | S11: 197 | T11: 397 | U11: 840
B12: 140 | C12: 181 | D12: 181 | E12: 372 | G12: 140 | H12: 174 | I12: 174 | J12: 373 | K12: 768 | L12: 140 | M12: 207 | N12: 207 | O12: 425 | Q12: 140 | R12: 199 | S12: 199 | T12: 426 | U12: 876
B13: 150 | C13: 181 | D13: 181 | E13: 394 | G13: 150 | H13: 174 | I13: 174 | J13: 396 | K13: 793 | L13: 150 | M13: 209 | N13: 209 | O13: 454 | Q13: 150 | R13: 201 | S13: 201 | T13: 456
